<?xml version="1.0" encoding="UTF-8"?>
<testng-results skipped="0" failed="1" ignored="0" total="1" passed="0">
  <reporter-output>
    <line>
      <![CDATA[test:testLogin Failed]]>
    </line>
  </reporter-output>
  <suite name="Default suite" duration-ms="40919" started-at="2018-10-08T07:54:39Z" finished-at="2018-10-08T07:55:20Z">
    <groups>
    </groups>
    <test name="Default test" duration-ms="40919" started-at="2018-10-08T07:54:39Z" finished-at="2018-10-08T07:55:20Z">
      <class name="script.LoginTest">
        <test-method status="PASS" signature="openApp()[pri:0, instance:script.LoginTest@3f4d3d]" name="openApp" is-config="true" duration-ms="22490" started-at="2018-10-08T07:54:39Z" finished-at="2018-10-08T07:55:02Z">
          <reporter-output>
          </reporter-output>
        </test-method> <!-- openApp -->
        <test-method status="FAIL" signature="testLogin()[pri:0, instance:script.LoginTest@3f4d3d]" name="testLogin" duration-ms="15393" started-at="2018-10-08T07:55:02Z" finished-at="2018-10-08T07:55:17Z">
          <exception class="java.lang.AssertionError">
            <message>
              <![CDATA[null]]>
            </message>
            <full-stacktrace>
              <![CDATA[java.lang.AssertionError: null
at org.testng.Assert.fail(Assert.java:96)
at org.testng.Assert.fail(Assert.java:103)
at script.LoginTest.testLogin(LoginTest.java:28)
at sun.reflect.NativeMethodAccessorImpl.invoke0(Native Method)
at sun.reflect.NativeMethodAccessorImpl.invoke(Unknown Source)
at sun.reflect.DelegatingMethodAccessorImpl.invoke(Unknown Source)
at java.lang.reflect.Method.invoke(Unknown Source)
at org.testng.internal.MethodInvocationHelper.invokeMethod(MethodInvocationHelper.java:124)
at org.testng.internal.Invoker.invokeMethod(Invoker.java:580)
at org.testng.internal.Invoker.invokeTestMethod(Invoker.java:716)
at org.testng.internal.Invoker.invokeTestMethods(Invoker.java:988)
at org.testng.internal.TestMethodWorker.invokeTestMethods(TestMethodWorker.java:125)
at org.testng.internal.TestMethodWorker.run(TestMethodWorker.java:109)
at org.testng.TestRunner.privateRun(TestRunner.java:648)
at org.testng.TestRunner.run(TestRunner.java:505)
at org.testng.SuiteRunner.runTest(SuiteRunner.java:455)
at org.testng.SuiteRunner.runSequentially(SuiteRunner.java:450)
at org.testng.SuiteRunner.privateRun(SuiteRunner.java:415)
at org.testng.SuiteRunner.run(SuiteRunner.java:364)
at org.testng.SuiteRunnerWorker.runSuite(SuiteRunnerWorker.java:52)
at org.testng.SuiteRunnerWorker.run(SuiteRunnerWorker.java:84)
at org.testng.TestNG.runSuitesSequentially(TestNG.java:1208)
at org.testng.TestNG.runSuitesLocally(TestNG.java:1137)
at org.testng.TestNG.runSuites(TestNG.java:1049)
at org.testng.TestNG.run(TestNG.java:1017)
at org.testng.remote.AbstractRemoteTestNG.run(AbstractRemoteTestNG.java:114)
at org.testng.remote.RemoteTestNG.initAndRun(RemoteTestNG.java:251)
at org.testng.remote.RemoteTestNG.main(RemoteTestNG.java:77)
]]>
            </full-stacktrace>
          </exception> <!-- java.lang.AssertionError -->
          <reporter-output>
          </reporter-output>
        </test-method> <!-- testLogin -->
        <test-method status="PASS" signature="closeApp(org.testng.ITestResult)[pri:0, instance:script.LoginTest@3f4d3d]" name="closeApp" is-config="true" duration-ms="2939" started-at="2018-10-08T07:55:17Z" finished-at="2018-10-08T07:55:20Z">
          <params>
            <param index="0">
              <value>
                <![CDATA[[TestResult name=testLogin status=FAILURE method=LoginTest.testLogin()[pri:0, instance:script.LoginTest@3f4d3d] output={null}]]]>
              </value>
            </param>
          </params>
          <reporter-output>
            <line>
              <![CDATA[test:testLogin Failed]]>
            </line>
          </reporter-output>
        </test-method> <!-- closeApp -->
      </class> <!-- script.LoginTest -->
    </test> <!-- Default test -->
  </suite> <!-- Default suite -->
</testng-results>
